<?xml version="1.0" ?>
<!-- =================================================================================== -->
<!-- |    This document was autogenerated by xacro from /home/kratnarajah/catkin_ws_PTU/src/flir_ptu/flir_ptu_description/urdf/example.urdf.xacro | -->
<!-- |    EDITING THIS FILE BY HAND IS NOT RECOMMENDED                                 | -->
<!-- =================================================================================== -->
<robot name="ptu_d46" xmlns:xacro="http://ros.org/wiki/xacro">
  <link name="base_link"/>
  <!-- Include and invoke the macro which creates a D46 -->
  <link name="ptu_pan_link">
    <!-- <inertial>
        <mass value="0.65" />
        <inertia ... ? />
      </inertial> -->
    <visual>
      <material name="ptu_body_color">
        <color rgba="0.3 0.3 0.3 1.0"/>
      </material>
      <geometry>
        <box size="0.045 0.065 0.044"/>
      </geometry>
      <origin xyz="0 0.011 0"/>
    </visual>
    <visual>
      <geometry>
        <box size="0.046 0.044 0.044"/>
      </geometry>
      <origin xyz="-0.045 0.0215 0"/>
    </visual>
    <visual>
      <geometry>
        <cylinder length="0.015" radius="0.005"/>
      </geometry>
      <origin rpy="0 1.57 0" xyz="-0.074 0.021 0"/>
    </visual>
  </link>
  <link name="ptu_tilt_link">
    <!-- <inertial>
        <mass value="0.65" />
        <inertia ... ? />
      </inertial> -->
    <visual>
      <material name="ptu_body_color">
        <color rgba="0.3 0.3 0.3 1.0"/>
      </material>
      <geometry>
        <box size="0.045 0.065 0.044"/>
      </geometry>
      <origin xyz="0 0.011 0"/>
    </visual>
    <visual>
      <geometry>
        <box size="0.046 0.044 0.044"/>
      </geometry>
      <origin xyz="-0.045 0.0215 0"/>
    </visual>
    <visual>
      <geometry>
        <cylinder length="0.015" radius="0.005"/>
      </geometry>
      <origin rpy="0 1.57 0" xyz="-0.074 0.021 0"/>
    </visual>
  </link>
  <link name="ptu_base_link"/>
  <link name="ptu_tilted_link"/>
  <link name="ptu_mount_link"/>
  <joint name="ptu_base" type="fixed">
    <parent link="ptu_base_link"/>
    <child link="ptu_pan_link"/>
    <origin xyz="0 -0.011 0.022"/>
  </joint>
  <joint name="ptu_pan" type="revolute">
    <parent link="ptu_pan_link"/>
    <origin rpy="-1.5708 0 0" xyz="0 0 0.066"/>
    <child link="ptu_tilt_link"/>
    <axis rpy="0 0 0" xyz="0 1 0"/>
    <limit effort="30" lower="2.775" upper="-2.775" velocity="1.0"/>
  </joint>
  <joint name="ptu_tilt" type="revolute">
    <parent link="ptu_tilt_link"/>
    <origin rpy="-1.5708 0 0" xyz="0 0 0"/>
    <child link="ptu_tilted_link"/>
    <axis xyz="0 1 0"/>
    <limit effort="30" lower="-0.82" upper="0.52" velocity="1.0"/>
  </joint>
  <joint name="ptu_mount" type="fixed">
    <parent link="ptu_tilted_link"/>
    <child link="ptu_mount_link"/>
    <origin rpy="3.1416 0 0" xyz="0 0 -0.03912"/>
  </joint>
  <!-- Create a fixed joint to connect the PTU to the rest of the robot -->
  <joint name="base_to_ptu_base" type="fixed">
    <parent link="base_link"/>
    <child link="ptu_base_link"/>
    <origin xyz="0 0 0"/>
  </joint>
  <!-- If you had a lidar or some other device mounted on the PTU, you would create another
       fixed joint here between the ptu_mount link and the origin of the device. -->
</robot>

